Workbook

Sheet FY 25
AH2: MORA | AQ2: ONA | BA2: MG | BM2: 80 | BN2: 80 | BO2: 80 | BP2: 80 | BQ2: 80 | BR2: 80 | BS2: 80 | BT2: 80 | BU2: 80 | BV2: 80 | BW2: 56
C3: 5124 | D3: 5134 | E3: 5145 | F3: 5147 | G3: 5164 | H3: 5166 | I3: 5173 | J3: 5174 | K3: 5175 | L3: 5176 | M3: 5208 | N3: 5209 | O3: 5211 | P3: 5227 | Q3: PC VA | R3: 5124 | S3: 5129 | T3: 5134 | U3: 5145 | V3: 5147 | W3: 5164 | X3: 5166 | Y3: 5173 | Z3: 5174 | AA3: 5175 | AB3: 5176 | AC3: 5208 | AD3: 5209 | AE3: 5211 | AF3: 5227 | AG3: PC MD | AH3: 2032 | AI3: 5051 | AJ3: 5052 | AK3: 5059 | AL3: 5140 | AM3: 5155 | AN3: 5187 | AO3: 5196 | AP3: MORA | AQ3: 5061 | AR3: 5062 | AS3: 5117 | AT3: 5118 | AU3: 5119 | AV3: 5151 | AW3: 5214 | AX3: 5215 | AY3: 5216 | AZ3: ONA | BA3: 5222 MD | BB3: 5189 MD | BC3: 5189 VA | BD3: 5222 VA | BE3: AFHS | BF3: VFHY | BG3: DV | BH3: NOFO | BI3: VOCA | BJ3: TVAP | BK3: G. Total | BL3: Hourly Rate | BM3: 45793 | BN3: 45807 | BO3: 45821 | BP3: 45835 | BQ3: 45849 | BR3: 45863 | BS3: 45877 | BT3: 45891 | BU3: 45905 | BV3: 45919 | BW3: 7 Days | BX3: Total | BY3: Balance
A4: 1 | B4: Jenna | Q4: =SUM(C4:P4) -> 0 | V4: =16619.68 -> 16619.68 | AG4: =SUM(R4:AF4) -> 16619.68 | AP4: =SUM(AH4:AO4) -> 0 | AZ4: =SUM(AQ4:AY4) -> 0 | BG4: 0 | BI4: 0 | BK4: =+Q4+AP4+AZ4+BE4+BH4+BI4+BJ4+BG4+AG4+BF4+BA4+BD4+BB4+BC4 -> 16619.68 | BL4: 24.0385 | BM4: 0 | BN4: 0 | BO4: =BO2*$BL$4 -> 1923.08 | BP4: =BP2*$BL$4 -> 1923.08 | BQ4: =BQ2*$BL$4 -> 1923.08 | BR4: =BR2*$BL$4 -> 1923.08 | BS4: =BS2*$BL$4 -> 1923.08 | BT4: =BT2*$BL$4 -> 1923.08 | BU4: =BU2*$BL$4 -> 1923.08 | BV4: =BV2*$BL$4 -> 1923.08 | BW4: =BW2*$BL$4 -> 1346.156 | BX4: =SUM(BM4:BW4) -> 16730.796 | BY4: =+BK4-BX4 -> -111.116
A5: 2 | B5: Abeer | Q5: =SUM(C5:P5) -> 0 | AG5: =SUM(R5:AF5) -> 0 | AP5: =SUM(AH5:AO5) -> 0 | BG5: 12973.01 | BI5: 947.92 | BJ5: 11917.33 | BK5: =+Q5+AP5+AZ5+BE5+BH5+BI5+BJ5+BG5+AG5+BF5+BA5+BD5+BB5+BC5 -> 25838.26 | BL5: 24.0385 | BM5: =$BM$2*$BL$6 -> 2048.08 | BN5: =$BM$2*$BL$6 -> 2048.08 | BO5: =$BM$2*$BL$6 -> 2048.08 | BP5: =$BM$2*$BL$6 -> 2048.08 | BQ5: =$BM$2*$BL$6 -> 2048.08 | BR5: =$BM$2*$BL$6 -> 2048.08 | BS5: =$BM$2*$BL$6 -> 2048.08 | BT5: =$BM$2*$BL$6 -> 2048.08 | ... BW5: =$BM$2*$BL$6 -> 2048.08 | BX5: =SUM(BM5:BW5) -> 22528.88 | BY5: =+BK5-BX5 -> 3309.38 | CA5: =+BL5*2080 -> 50000.08
A6: 3 | B6: ABI | Q6: =SUM(C6:P6) -> 0 | AG6: =SUM(R6:AF6) -> 0 | AP6: =SUM(AH6:AO6) -> 0 | AS6: 13753.82 | AT6: 15253.83 | AZ6: =SUM(AQ6:AY6) -> 29007.65 | BK6: =+Q6+AP6+AZ6+BE6+BH6+BI6+BJ6+BG6+AG6+BF6+BA6+BD6+BB6+BC6 -> 29007.65 | BL6: 25.601 | BM6: =$BM$2*$BL$6 -> 2048.08 | BN6: =$BM$2*$BL$6 -> 2048.08 | BO6: =$BM$2*$BL$6 -> 2048.08 | BP6: =$BM$2*$BL$6 -> 2048.08 | BQ6: =$BM$2*$BL$6 -> 2048.08 | BR6: =$BM$2*$BL$6 -> 2048.08 | BS6: =$BM$2*$BL$6 -> 2048.08 | BT6: =$BM$2*$BL$6 -> 2048.08 | ... BW6: =$BM$2*$BL$6 -> 2048.08 | BX6: =SUM(BM6:BW6) -> 22528.88 | BY6: =+BK6-BX6 -> 6478.77 | CA6: =+BL6*2080 -> 53250.08
A7: =+A6+1 -> 4 | B7: Aemal | Q7: =SUM(C7:P7) -> 0 | AG7: =SUM(R7:AF7) -> 0 | AP7: =SUM(AH7:AO7) -> 0 | AT7: 29538.41 | AZ7: =SUM(AQ7:AY7) -> 29538.41 | BK7: =+Q7+AP7+AZ7+BE7+BH7+BI7+BJ7+BG7+AG7+BF7+BA7+BD7+BB7+BC7 -> 29538.41 | BL7: 26.4423 | BM7: =+$BL$7*BM2 -> 2115.384 | BN7: =+$BL$7*BN2 -> 2115.384 | BO7: =+$BL$7*BO2 -> 2115.384 | BP7: =+$BL$7*BP2 -> 2115.384 | BQ7: =+$BL$7*BQ2 -> 2115.384 | BR7: =+$BL$7*BR2 -> 2115.384 | BS7: =+$BL$7*BS2 -> 2115.384 | BT7: =+$BL$7*BT2 -> 2115.384 | ... BW7: =+$BL$7*BW2 -> 1480.7688 | BX7: =SUM(BM7:BW7) -> 22634.609 | BY7: =+BK7-BX7 -> 6903.8012 | CA7: =+BL7*2080 -> 54999.984
A8: =+A7+1 -> 5 | B8: Ahmed Seyar Auobi | F8: 2240.39 | J8: 8644.19 | L8: 11000 | N8: 397.92 | O8: 1685.37 | Q8: =SUM(C8:P8) -> 23967.87 | AG8: =SUM(R8:AF8) -> 0 | AH8: 0 | AI8: 0 | AP8: =SUM(AH8:AO8) -> 0 | AZ8: =SUM(AQ8:AY8) -> 0 | BK8: =+Q8+AP8+AZ8+BE8+BH8+BI8+BJ8+BG8+AG8+BF8+BA8+BD8+BB8+BC8 -> 23967.87 | BL8: 24.0385 | BM8: =+$BL$8*BM2 -> 1923.08 | BN8: =+$BL$8*BN2 -> 1923.08 | BO8: =+$BL$8*BO2 -> 1923.08 | BP8: =+$BL$8*BP2 -> 1923.08 | BQ8: =+$BL$8*BQ2 -> 1923.08 | BR8: =+$BL$8*BR2 -> 1923.08 | BS8: =+$BL$8*BS2 -> 1923.08 | BT8: =+$BL$8*BT2 -> 1923.08 | ... BW8: =+$BL$8*BW2 -> 1346.156 | BX8: =SUM(BM8:BW8) -> 20576.956 | BY8: =+BK8-BX8 -> 3390.914 | CA8: =+BL8*2080 -> 50000.08
A9: =+A8+1 -> 6 | B9: Ajmal Amiri | G9: 2463.21 | N9: 23766.74 | Q9: =SUM(C9:P9) -> 26229.95 | AG9: =SUM(R9:AF9) -> 0 | AH9: 0 | AI9: 0 | AP9: =SUM(AH9:AO9) -> 0 | AZ9: =SUM(AQ9:AY9) -> 0 | BK9: =+Q9+AP9+AZ9+BE9+BH9+BI9+BJ9+BG9+AG9+BF9+BA9+BD9+BB9+BC9 -> 26229.95 | BL9: 25.601 | BM9: =$BL$9*BM2 -> 2048.08 | BN9: =$BL$9*BN2 -> 2048.08 | BO9: =$BL$9*BO2 -> 2048.08 | BP9: =$BL$9*BP2 -> 2048.08 | BQ9: =$BL$9*BQ2 -> 2048.08 | BR9: =$BL$9*BR2 -> 2048.08 | BS9: =$BL$9*BS2 -> 2048.08 | BT9: =$BL$9*BT2 -> 2048.08 | ... BW9: =$BL$9*BW2 -> 1433.656 | BX9: =SUM(BM9:BW9) -> 21914.456 | BY9: =+BK9-BX9 -> 4315.494 | CA9: =+BL9*2080 -> 53250.08
A10: =+A9+1 -> 7 | B10: Akilu Debalkew | H10: 10115.38 | J10: 375.5 | L10: 2405.77 | O10: 140.19 | P10: 9000 | Q10: =SUM(C10:P10) -> 22036.84 | AC10: 93.46 | AG10: =SUM(R10:AF10) -> 93.46 | AH10: 0 | AI10: 0 | AP10: =SUM(AH10:AO10) -> 0 | AZ10: =SUM(AQ10:AY10) -> 0 | BA10: 2000 | BC10: 1923.08 | BK10: =+Q10+AP10+AZ10+BE10+BH10+BI10+BJ10+BG10+AG10+BF10+BA10+BD10+BB10+BC10 -> 26053.38 | BL10: 24.0385 | BM10: =+$BL$10*BM2 -> 1923.08 | BN10: =+$BL$10*BN2 -> 1923.08 | BO10: =+$BL$10*BO2 -> 1923.08 | BP10: =+$BL$10*BP2 -> 1923.08 | BQ10: =+$BL$10*BQ2 -> 1923.08 | BR10: =+$BL$10*BR2 -> 1923.08 | BS10: =+$BL$10*BS2 -> 1923.08 | BT10: =+$BL$10*BT2 -> 1923.08 | ... BW10: =+$BL$10*BW2 -> 1346.156 | BX10: =SUM(BM10:BW10) -> 20576.956 | BY10: =+BK10-BX10 -> 5476.424 | CA10: =+BL10*2080 -> 50000.08
A11: =+A10+1 -> 8 | B11: Ajmal Khurram | Q11: =SUM(C11:P11) -> 0 | AG11: =SUM(R11:AF11) -> 0 | AK11: 33615.34 | AP11: =SUM(AH11:AO11) -> 33615.34 | AZ11: =SUM(AQ11:AY11) -> 0 | BK11: =+Q11+AP11+AZ11+BE11+BH11+BI11+BJ11+BG11+AG11+BF11+BA11+BD11+BB11+BC11 -> 33615.34 | BL11: 24.0385 | BM11: 0 | BN11: 0 | BO11: =+$BL$11*BO2 -> 1923.08 | BP11: =+$BL$11*BP2 -> 1923.08 | BQ11: =+$BL$11*BQ2 -> 1923.08 | BR11: =+$BL$11*BR2 -> 1923.08 | BS11: =+$BL$11*BS2 -> 1923.08 | BT11: =+$BL$11*BT2 -> 1923.08 | BU11: =+$BL$11*BU2 -> 1923.08 | BV11: =+$BL$11*BV2 -> 1923.08 | BW11: =+$BL$11*BW2 -> 1346.156 | BX11: =SUM(BM11:BW11) -> 16730.796 | BY11: =+BK11-BX11 -> 16884.544 | CA11: =+BL11*2080 -> 50000.08
A12: =+A11+1 -> 9 | B12: Anna Kurzer | Q12: =SUM(C12:P12) -> 0 | AG12: =SUM(R12:AF12) -> 0 | AK12: 20162.55 | AL12: 731 | AP12: =SUM(AH12:AO12) -> 20893.55 | AZ12: =SUM(AQ12:AY12) -> 0 | BA12: 8653.14 | BB12: 499.22 | BK12: =+Q12+AP12+AZ12+BE12+BH12+BI12+BJ12+BG12+AG12+BF12+BA12+BD12+BB12+BC12 -> 30045.91 | BL12: 33.2813 | BM12: =+$BL$12*BM2 -> 2662.504 | BN12: =+$BL$12*BN2 -> 2662.504 | BO12: =+$BL$12*BO2 -> 2662.504 | BP12: =+$BL$12*BP2 -> 2662.504 | BQ12: =+$BL$12*BQ2 -> 2662.504 | BR12: =+$BL$12*BR2 -> 2662.504 | BS12: =+$BL$12*BS2 -> 2662.504 | BT12: =+$BL$12*BT2 -> 2662.504 | ... BW12: =+$BL$12*BW2 -> 1863.7528 | BX12: =SUM(BM12:BW12) -> 28488.793 | BY12: =+BK12-BX12 -> 1557.1172 | CA12: =+BL12*2080 -> 69225.104
A13: =+A12+1 -> 10 | B13: Annie Phillips | F13: 7190.38 | I13: 53.45 | L13: 1000 | M13: 2199 | Q13: =SUM(C13:P13) -> 10442.83 | AG13: =SUM(R13:AF13) -> 0 | AH13: 0 | AI13: 0 | AP13: =SUM(AH13:AO13) -> 0 | AQ13: 156.31 | AV13: 23586.88 | AZ13: =SUM(AQ13:AY13) -> 23743.19 | BK13: =+Q13+AP13+AZ13+BE13+BH13+BI13+BJ13+BG13+AG13+BF13+BA13+BD13+BB13+BC13 -> 34186.02 | BL13: 32.6923 | BM13: =+$BL$13*BM2 -> 2615.384 | BN13: =+$BL$13*BN2 -> 2615.384 | BO13: =+$BL$13*BO2 -> 2615.384 | BP13: =+$BL$13*BP2 -> 2615.384 | BQ13: =+$BL$13*BQ2 -> 2615.384 | BR13: =+$BL$13*BR2 -> 2615.384 | BS13: =+$BL$13*BS2 -> 2615.384 | BT13: =+$BL$13*BT2 -> 2615.384 | ... BW13: =+$BL$13*BW2 -> 1830.7688 | BX13: =SUM(BM13:BW13) -> 27984.609 | BY13: =+BK13-BX13 -> 6201.4112 | CA13: =+BL13*2080 -> 67999.984
A14: =+A13+1 -> 11 | B14: Atakhleti | Q14: =SUM(C14:P14) -> 0 | AG14: =SUM(R14:AF14) -> 0 | AP14: =SUM(AH14:AO14) -> 0 | AZ14: =SUM(AQ14:AY14) -> 0 | BH14: =39347.44-40.09-6000 -> 33307.35 | BK14: =+Q14+AP14+AZ14+BE14+BH14+BI14+BJ14+BG14+AG14+BF14+BA14+BD14+BB14+BC14 -> 33307.35 | BL14: 32.7064 | BM14: =+$BL$14*BM2 -> 2616.512 | BN14: =+$BL$14*BN2 -> 2616.512 | BO14: =+$BL$14*BO2 -> 2616.512 | BP14: =+$BL$14*BP2 -> 2616.512 | BQ14: =+$BL$14*BQ2 -> 2616.512 | BR14: =+$BL$14*BR2 -> 2616.512 | BS14: =+$BL$14*BS2 -> 2616.512 | BT14: =+$BL$14*BT2 -> 2616.512 | ... BW14: =+$BL$14*BW2 -> 1831.5584 | BX14: =SUM(BM14:BW14) -> 27996.678 | BY14: =+BK14-BX14 -> 5310.6716 | CA14: =+BL14*2080 -> 68029.312
A15: =+A14+1 -> 12 | B15: Baig | Q15: =SUM(C15:P15) -> 0 | AG15: =SUM(R15:AF15) -> 0 | AP15: =SUM(AH15:AO15) -> 0 | AT15: 29843.76 | AZ15: =SUM(AQ15:AY15) -> 29843.76 | BK15: =+Q15+AP15+AZ15+BE15+BH15+BI15+BJ15+BG15+AG15+BF15+BA15+BD15+BB15+BC15 -> 29843.76 | BL15: 27.7771 | BM15: =+$BL$15*BM2 -> 2222.168 | BN15: =+$BL$15*BN2 -> 2222.168 | BO15: =+$BL$15*BO2 -> 2222.168 | BP15: =+$BL$15*BP2 -> 2222.168 | BQ15: =+$BL$15*BQ2 -> 2222.168 | BR15: =+$BL$15*BR2 -> 2222.168 | BS15: =+$BL$15*BS2 -> 2222.168 | BT15: =+$BL$15*BT2 -> 2222.168 | ... BW15: =+$BL$15*BW2 -> 1555.5176 | BX15: =SUM(BM15:BW15) -> 23777.198 | BY15: =+BK15-BX15 -> 6066.5624 | CA15: =+BL15*2080 -> 57776.368 | CB15: =+BL15*2080 -> 57776.368
A16: =+A15+1 -> 13 | B16: Barbara Callen | D16: 731.25 | H16: 5281.25 | I16: 1635.64 | J16: 966.58 | M16: 2112.5 | N16: 925 | O16: 1400 | P16: 4052.39 | Q16: =SUM(C16:P16) -> 17104.61 | Z16: 464.47 | AC16: 1400 | AD16: 2800 | AE16: 1400 | AG16: =SUM(R16:AF16) -> 6064.47 | AH16: 0 | AI16: 0 | AK16: 68.75 | AM16: 0 | AO16: 2127.87 | AP16: =SUM(AH16:AO16) -> 2196.62 | AQ16: 700 | AR16: 700 | AW16: 150 | AX16: 1725 | AY16: 1400 | AZ16: =SUM(AQ16:AY16) -> 4675 | BA16: 3250 | BB16: 687.5 | BC16: 687.5 | BD16: 1625 | BI16: 2368.41 | BK16: =+Q16+AP16+AZ16+BE16+BH16+BI16+BJ16+BG16+AG16+BF16+BA16+BD16+BB16+BC16 -> 38659.11 | BL16: 31.25 | BM16: =+$BL$16*BM2 -> 2500 | BN16: =+$BL$16*BN2 -> 2500 | BO16: =+$BL$16*BO2 -> 2500 | BP16: =+$BL$16*BP2 -> 2500 | BQ16: =+$BL$16*BQ2 -> 2500 | BR16: =+$BL$16*BR2 -> 2500 | BS16: =+$BL$16*BS2 -> 2500 | BT16: =+$BL$16*BT2 -> 2500 | ... BW16: =+$BL$16*BW2 -> 1750 | BX16: =SUM(BM16:BW16) -> 26750 | BY16: =+BK16-BX16 -> 11909.11 | CA16: =+BL16*2080 -> 65000
A17: =+A16+1 -> 14 | B17: Baryalai Rawan | Q17: =SUM(C17:P17) -> 0 | T17: 2345.89 | V17: 646.05 | Y17: 486.11 | AB17: 9574.88 | AC17: 7793.73 | AG17: =SUM(R17:AF17) -> 20846.66 | AH17: 3643.12 | AI17: 668.02 | AJ17: 8300.96 | AP17: =SUM(AH17:AO17) -> 12612.1 | AZ17: =SUM(AQ17:AY17) -> 0 | BK17: =+Q17+AP17+AZ17+BE17+BH17+BI17+BJ17+BG17+AG17+BF17+BA17+BD17+BB17+BC17 -> 33458.76 | BL17: 32.6923 | BM17: =+$BL$17*BM2 -> 2615.384 | BN17: =+$BL$17*BN2 -> 2615.384 | BO17: =+$BL$17*BO2 -> 2615.384 | BP17: =+$BL$17*BP2 -> 2615.384 | BQ17: =+$BL$17*BQ2 -> 2615.384 | BR17: =+$BL$17*BR2 -> 2615.384 | BS17: =+$BL$17*BS2 -> 2615.384 | BT17: =+$BL$17*BT2 -> 2615.384 | ... BW17: =+$BL$17*BW2 -> 1830.7688 | BX17: =SUM(BM17:BW17) -> 27984.609 | BY17: =+BK17-BX17 -> 5474.1512 | CA17: =+BL17*2080 -> 67999.984
A18: =+A17+1 -> 15 | B18: Bethelem | Q18: =SUM(C18:P18) -> 0 | AG18: =SUM(R18:AF18) -> 0 | AK18: 31625.12 | AP18: =SUM(AH18:AO18) -> 31625.12 | AZ18: =SUM(AQ18:AY18) -> 0 | BK18: =+Q18+AP18+AZ18+BE18+BH18+BI18+BJ18+BG18+AG18+BF18+BA18+BD18+BB18+BC18 -> 31625.12 | BL18: 24.0385 | BM18: =+$BL$18*BM2 -> 1923.08 | BN18: =+$BL$18*BN2 -> 1923.08 | BO18: =+$BL$18*BO2 -> 1923.08 | BP18: =+$BL$18*BP2 -> 1923.08 | BQ18: =+$BL$18*BQ2 -> 1923.08 | BR18: =+$BL$18*BR2 -> 1923.08 | BS18: =+$BL$18*BS2 -> 1923.08 | BT18: =+$BL$18*BT2 -> 1923.08 | ... BW18: =+$BL$18*BW2 -> 1346.156 | BX18: =SUM(BM18:BW18) -> 20576.956 | BY18: =+BK18-BX18 -> 11048.164 | CA18: =+BL18*2080 -> 50000.08
A19: =+A18+1 -> 16 | B19: Bob Elston | F19: =2948.9+562.5 -> 3511.4 | H19: 1374.99 | P19: 13000 | Q19: =SUM(C19:P19) -> 17886.39 | X19: 9906.25 | AG19: =SUM(R19:AF19) -> 9906.25 | AH19: 0 | AI19: 0 | AP19: =SUM(AH19:AO19) -> 0 | AW19: 1587.5 | AX19: 1506.25 | AZ19: =SUM(AQ19:AY19) -> 3093.75 | BA19: 3250 | BK19: =+Q19+AP19+AZ19+BE19+BH19+BI19+BJ19+BG19+AG19+BF19+BA19+BD19+BB19+BC19 -> 34136.39 | BL19: 31.25 | BM19: =+$BL$19*BM2 -> 2500 | BN19: =+$BL$19*BN2 -> 2500 | BO19: =+$BL$19*BO2 -> 2500 | BP19: =+$BL$19*BP2 -> 2500 | BQ19: =+$BL$19*BQ2 -> 2500 | BR19: =+$BL$19*BR2 -> 2500 | BS19: =+$BL$19*BS2 -> 2500 | BT19: =+$BL$19*BT2 -> 2500 | ... BW19: =+$BL$19*BW2 -> 1750 | BX19: =SUM(BM19:BW19) -> 26750 | BY19: =+BK19-BX19 -> 7386.39 | CA19: =+BL19*2080 -> 65000
A20: 17 | B20: TBH - Lia Russel | Q20: =SUM(C20:P20) -> 0 | AG20: =SUM(R20:AF20) -> 0 | BD20: 18750 | BK20: =+Q20+AP20+AZ20+BE20+BH20+BI20+BJ20+BG20+AG20+BF20+BA20+BD20+BB20+BC20 -> 18750 | BL20: =55000/2080 -> 26.442308 | BP20: =+BL20*BP2 -> 2115.3846 | BQ20: =+BP20 -> 2115.3846 | BR20: =+BQ20 -> 2115.3846 | BS20: =+BR20 -> 2115.3846 | BT20: =+BS20 -> 2115.3846 | BU20: =+BT20 -> 2115.3846 | BV20: =+BU20 -> 2115.3846 | BW20: =+BL20*56 -> 1480.7692 | BX20: =SUM(BM20:BW20) -> 16288.462 | BY20: =+BK20-BX20 -> 2461.5385 | CA20: =+BL20*2080 -> 55000
A21: 18 | B21: Christina | Q21: =SUM(C21:P21) -> 0 | AG21: =SUM(R21:AF21) -> 0 | AP21: =SUM(AH21:AO21) -> 0 | AT21: 26682.65 | AZ21: =SUM(AQ21:AY21) -> 26682.65 | BD21: 0 | BK21: =+Q21+AP21+AZ21+BE21+BH21+BI21+BJ21+BG21+AG21+BF21+BA21+BD21+BB21+BC21 -> 26682.65 | BL21: 25.601 | BM21: =+$BL$21*BM2 -> 2048.08 | BN21: =+$BL$21*BN2 -> 2048.08 | BO21: =+$BL$21*BO2 -> 2048.08 | BP21: =+$BL$21*BP2 -> 2048.08 | BQ21: =+$BL$21*BQ2 -> 2048.08 | BR21: =+$BL$21*BR2 -> 2048.08 | BS21: =+$BL$21*BS2 -> 2048.08 | BT21: =+$BL$21*BT2 -> 2048.08 | ... BW21: =+$BL$21*BW2 -> 1433.656 | BX21: =SUM(BM21:BW21) -> 21914.456 | BY21: =+BK21-BX21 -> 4768.194 | CA21: =+BL21*2080 -> 53250.08
A22: =+A21+1 -> 19 | B22: Cynthia Cole | Q22: =SUM(C22:P22) -> 0 | R22: 26915.7 | V22: 3416.98 | AG22: =SUM(R22:AF22) -> 30332.68 | AJ22: 2984.13 | AP22: =SUM(AH22:AO22) -> 2984.13 | AZ22: =SUM(AQ22:AY22) -> 0 | BI22: 0 | BJ22: 0 | BK22: =+Q22+AP22+AZ22+BE22+BH22+BI22+BJ22+BG22+AG22+BF22+BA22+BD22+BB22+BC22 -> 33316.81 | BL22: 30.5547 | BM22: =+$BL$22*BM2 -> 2444.376 | BN22: =+$BL$22*BN2 -> 2444.376 | BO22: =+$BL$22*BO2 -> 2444.376 | BP22: =+$BL$22*BP2 -> 2444.376 | BQ22: =+$BL$22*BQ2 -> 2444.376 | BR22: =+$BL$22*BR2 -> 2444.376 | BS22: =+$BL$22*BS2 -> 2444.376 | BT22: =+$BL$22*BT2 -> 2444.376 | ... BW22: =+$BL$22*BW2 -> 1711.0632 | BX22: =SUM(BM22:BW22) -> 26154.823 | BY22: =+BK22-BX22 -> 7161.9868 | CA22: =+BL22*2080 -> 63553.776
A23: =+A22+1 -> 20 | B23: Dagim McKonnen | Q23: =SUM(C23:P23) -> 0 | AG23: =SUM(R23:AF23) -> 0 | AK23: 31849.97 | AP23: =SUM(AH23:AO23) -> 31849.97 | AZ23: =SUM(AQ23:AY23) -> 0 | BK23: =+Q23+AP23+AZ23+BE23+BH23+BI23+BJ23+BG23+AG23+BF23+BA23+BD23+BB23+BC23 -> 31849.97 | BL23: 30.5547 | BM23: =+$BL$23*BM2 -> 2444.376 | BN23: =+$BL$23*BN2 -> 2444.376 | BO23: =+$BL$23*BO2 -> 2444.376 | BP23: =+$BL$23*BP2 -> 2444.376 | BQ23: =+$BL$23*BQ2 -> 2444.376 | BR23: =+$BL$23*BR2 -> 2444.376 | BS23: =+$BL$23*BS2 -> 2444.376 | BT23: =+$BL$23*BT2 -> 2444.376 | ... BW23: =+$BL$23*BW2 -> 1711.0632 | BX23: =SUM(BM23:BW23) -> 26154.823 | BY23: =+BK23-BX23 -> 5695.1468 | CA23: =+BL23*2080 -> 63553.776
A24: =+A23+1 -> 21 | B24: Desiree | Q24: =SUM(C24:P24) -> 0 | S24: 413.44 | U24: 683.51 | X24: 14021.38 | AE24: 1600 | AF24: 7051.92 | AG24: =SUM(R24:AF24) -> 23770.25 | AK24: 10396.92 | AL24: 800 | AO24: 1574.4 | AP24: =SUM(AH24:AO24) -> 12771.32 | AZ24: =SUM(AQ24:AY24) -> 0 | BA24: 3800 | BK24: =+Q24+AP24+AZ24+BE24+BH24+BI24+BJ24+BG24+AG24+BF24+BA24+BD24+BB24+BC24 -> 40341.57 | BL24: 36.5385 | BM24: =+$BL$24*BM2 -> 2923.08 | BN24: =+$BL$24*BN2 -> 2923.08 | BO24: =+$BL$24*BO2 -> 2923.08 | BP24: =+$BL$24*BP2 -> 2923.08 | BQ24: =+$BL$24*BQ2 -> 2923.08 | BR24: =+$BL$24*BR2 -> 2923.08 | BS24: =+$BL$24*BS2 -> 2923.08 | BT24: =+$BL$24*BT2 -> 2923.08 | ... BW24: =+$BL$24*BW2 -> 2046.156 | BX24: =SUM(BM24:BW24) -> 31276.956 | BY24: =+BK24-BX24 -> 9064.614 | CA24: =+BL24*2080 -> 76000.08
A25: =+A24+1 -> 22 | B25: Earnest | Q25: =SUM(C25:P25) -> 0 | AG25: =SUM(R25:AF25) -> 0 | AP25: =SUM(AH25:AO25) -> 0 | AT25: 26255.11 | AZ25: =SUM(AQ25:AY25) -> 26255.11 | BK25: =+Q25+AP25+AZ25+BE25+BH25+BI25+BJ25+BG25+AG25+BF25+BA25+BD25+BB25+BC25 -> 26255.11 | BL25: 24.0385 | BM25: =+$BL$25*BM2 -> 1923.08 | BN25: =+$BL$25*BN2 -> 1923.08 | BO25: =+$BL$25*BO2 -> 1923.08 | BP25: =+$BL$25*BP2 -> 1923.08 | BQ25: =+$BL$25*BQ2 -> 1923.08 | BR25: =+$BL$25*BR2 -> 1923.08 | BS25: =+$BL$25*BS2 -> 1923.08 | BT25: =+$BL$25*BT2 -> 1923.08 | ... BW25: =+$BL$25*BW2 -> 1346.156 | BX25: =SUM(BM25:BW25) -> 20576.956 | BY25: =+BK25-BX25 -> 5678.154 | CA25: =+BL25*2080 -> 50000.08
A26: =+A25+1 -> 23 | B26: Eftihia | Q26: =SUM(C26:P26) -> 0 | AG26: =SUM(R26:AF26) -> 0 | AP26: =SUM(AH26:AO26) -> 0 | AS26: 33624.85 | AZ26: =SUM(AQ26:AY26) -> 33624.85 | BK26: =+Q26+AP26+AZ26+BE26+BH26+BI26+BJ26+BG26+AG26+BF26+BA26+BD26+BB26+BC26 -> 33624.85 | BL26: 32.2571 | BM26: =+$BL$26*BM2 -> 2580.568 | BN26: =+$BL$26*BN2 -> 2580.568 | BO26: =+$BL$26*BO2 -> 2580.568 | BP26: =+$BL$26*BP2 -> 2580.568 | BQ26: =+$BL$26*BQ2 -> 2580.568 | BR26: =+$BL$26*BR2 -> 2580.568 | BS26: =+$BL$26*BS2 -> 2580.568 | BT26: =+$BL$26*BT2 -> 2580.568 | ... BW26: =+$BL$26*BW2 -> 1806.3976 | BX26: =SUM(BM26:BW26) -> 27612.078 | BY26: =+BK26-BX26 -> 6012.7724 | CA26: =+BL26*2080 -> 67094.768
A27: =+A26+1 -> 24 | B27: Egosia | Q27: =SUM(C27:P27) -> 0 | AG27: =SUM(R27:AF27) -> 0 | AL27: 26686.63 | AP27: =SUM(AH27:AO27) -> 26686.63 | AZ27: =SUM(AQ27:AY27) -> 0 | BK27: =+Q27+AP27+AZ27+BE27+BH27+BI27+BJ27+BG27+AG27+BF27+BA27+BD27+BB27+BC27 -> 26686.63 | BL27: 25.601 | BM27: =+$BL$27*BM2 -> 2048.08 | BN27: =+$BL$27*BN2 -> 2048.08 | BO27: =+$BL$27*BO2 -> 2048.08 | BP27: =+$BL$27*BP2 -> 2048.08 | BQ27: =+$BL$27*BQ2 -> 2048.08 | BR27: =+$BL$27*BR2 -> 2048.08 | BS27: =+$BL$27*BS2 -> 2048.08 | BT27: =+$BL$27*BT2 -> 2048.08 | ... BW27: =+$BL$27*BW2 -> 1433.656 | BX27: =SUM(BM27:BW27) -> 21914.456 | BY27: =+BK27-BX27 -> 4772.174 | CA27: =+BL27*2080 -> 53250.08
A28: =+A27+1 -> 25 | B28: Elizaabeth | Q28: =SUM(C28:P28) -> 0 | AG28: =SUM(R28:AF28) -> 0 | AM28: 29397.74 | AP28: =SUM(AH28:AO28) -> 29397.74 | AZ28: =SUM(AQ28:AY28) -> 0 | BK28: =+Q28+AP28+AZ28+BE28+BH28+BI28+BJ28+BG28+AG28+BF28+BA28+BD28+BB28+BC28 -> 29397.74 | BL28: 28.161 | BM28: =+$BL$28*BM2 -> 2252.88 | BN28: =+$BL$28*BN2 -> 2252.88 | BO28: =+$BL$28*BO2 -> 2252.88 | BP28: =+$BL$28*BP2 -> 2252.88 | BQ28: =+$BL$28*BQ2 -> 2252.88 | BR28: =+$BL$28*BR2 -> 2252.88 | BS28: =+$BL$28*BS2 -> 2252.88 | BT28: =+$BL$28*BT2 -> 2252.88 | ... BW28: =+$BL$28*BW2 -> 1577.016 | BX28: =SUM(BM28:BW28) -> 24105.816 | BY28: =+BK28-BX28 -> 5291.924 | CA28: =+BL28*2080 -> 58574.88
A29: =+A28+1 -> 26 | B29: Emebet Ashagre | H29: 5653.86 | M29: 1558.65 | O29: 926.92 | Q29: =SUM(C29:P29) -> 8139.43 | S29: 8031.41 | AC29: 1600 | AE29: 2000 | AF29: 3500 | AG29: =SUM(R29:AF29) -> 15131.41 | AH29: 0 | AI29: 0 | AP29: =SUM(AH29:AO29) -> 0 | AS29: 3648.07 | AT29: 875.97 | AV29: 3745.18 | AW29: 1600 | AY29: 1600 | AZ29: =SUM(AQ29:AY29) -> 11469.22 | BD29: 2100 | BK29: =+Q29+AP29+AZ29+BE29+BH29+BI29+BJ29+BG29+AG29+BF29+BA29+BD29+BB29+BC29 -> 36840.06 | BL29: 33.6539 | BM29: =+$BL$29*BM2 -> 2692.312 | BN29: =+$BL$29*BN2 -> 2692.312 | BO29: =+$BL$29*BO2 -> 2692.312 | BP29: =+$BL$29*BP2 -> 2692.312 | BQ29: =+$BL$29*BQ2 -> 2692.312 | BR29: =+$BL$29*BR2 -> 2692.312 | BS29: =+$BL$29*BS2 -> 2692.312 | BT29: =+$BL$29*BT2 -> 2692.312 | ... BW29: =+$BL$29*BW2 -> 1884.6184 | BX29: =SUM(BM29:BW29) -> 28807.738 | BY29: =+BK29-BX29 -> 8032.3216 | CA29: =+BL29*2080 -> 70000.112
A30: 27 | B30: TBH - Marc Aldor | Q30: =SUM(C30:P30) -> 0 | AD30: 28336.18 | AG30: =SUM(R30:AF30) -> 28336.18 | BK30: =+Q30+AP30+AZ30+BE30+BH30+BI30+BJ30+BG30+AG30+BF30+BA30+BD30+BB30+BC30 -> 28336.18 | BY30: =+BK30-BX30 -> 28336.18 | CA30: =+BL30*2080 -> 0
A31: 28 | B31: TBH - Employment Speecialist | N31: 26000 | Q31: =SUM(C31:P31) -> 26000 | AD31: 0 | AG31: =SUM(R31:AF31) -> 0 | AJ31: 0 | AK31: 0 | AP31: =SUM(AH31:AO31) -> 0 | AT31: 0 | AZ31: =SUM(AQ31:AY31) -> 0 | BD31: 0 | BK31: =+Q31+AP31+AZ31+BE31+BH31+BI31+BJ31+BG31+AG31+BF31+BA31+BD31+BB31+BC31 -> 26000 | BL31: 0 | BM31: =+$BL$31*BM2 -> 0 | BN31: =+$BL$31*BN2 -> 0 | BO31: =+$BL$31*BO2 -> 0 | BP31: =+$BL$31*BP2 -> 0 | BQ31: =+$BL$31*BQ2 -> 0 | BR31: =+$BL$31*BR2 -> 0 | BS31: =+$BL$31*BS2 -> 0 | BT31: =+$BL$31*BT2 -> 0 | ... BW31: =+$BL$31*BW2 -> 0 | BX31: =SUM(BM31:BW31) -> 0 | BY31: =+BK31-BX31 -> 26000 | CA31: =+BL31*2080 -> 0
A32: =+A31+1 -> 29 | B32: Esra Bayrakthar | F32: 3192.92 | L32: 178.86 | Q32: =SUM(C32:P32) -> 3371.78 | AG32: =SUM(R32:AF32) -> 0 | AH32: 0 | AI32: 0 | AJ32: 3980.05 | AP32: =SUM(AH32:AO32) -> 3980.05 | AT32: 37176.16 | AZ32: =SUM(AQ32:AY32) -> 37176.16 | BK32: =+Q32+AP32+AZ32+BE32+BH32+BI32+BJ32+BG32+AG32+BF32+BA32+BD32+BB32+BC32 -> 44527.99 | BL32: 40.9583 | BM32: =+$BL$32*BM2 -> 3276.664 | BN32: =+$BL$32*BN2 -> 3276.664 | BO32: =+$BL$32*BO2 -> 3276.664 | BP32: =+$BL$32*BP2 -> 3276.664 | BQ32: =+$BL$32*BQ2 -> 3276.664 | BR32: =+$BL$32*BR2 -> 3276.664 | BS32: =+$BL$32*BS2 -> 3276.664 | BT32: =+$BL$32*BT2 -> 3276.664 | ... BW32: =+$BL$32*BW2 -> 2293.6648 | BX32: =SUM(BM32:BW32) -> 35060.305 | BY32: =+BK32-BX32 -> 9467.6852 | CA32: =+BL32*2080 -> 85193.264
A33: =+A32+1 -> 30 | B33: Evette | Q33: =SUM(C33:P33) -> 0 | S33: 13036 | V33: 1084 | AG33: =SUM(R33:AF33) -> 14120 | AP33: =SUM(AH33:AO33) -> 0 | AZ33: =SUM(AQ33:AY33) -> 0 | BK33: =+Q33+AP33+AZ33+BE33+BH33+BI33+BJ33+BG33+AG33+BF33+BA33+BD33+BB33+BC33 -> 14120 | BL33: 20 | BM33: =+$BL$33*70 -> 1400 | BN33: =+$BL$33*70 -> 1400 | BO33: =+$BL$33*70 -> 1400 | BP33: =+$BL$33*70 -> 1400 | BQ33: =+$BL$33*70 -> 1400 | BR33: =+$BL$33*70 -> 1400 | BS33: =+$BL$33*70 -> 1400 | BT33: =+$BL$33*70 -> 1400 | ... BV33: =+$BL$33*70 -> 1400 | BW33: 0 | BX33: =SUM(BM33:BW33) -> 14000 | BY33: =+BK33-BX33 -> 120 | CA33: =+BL33*2080 -> 41600
A34: =+A33+1 -> 31 | B34: TBH - FatIh Casken | Q34: =SUM(C34:P34) -> 0 | AG34: =SUM(R34:AF34) -> 0 | AK34: 35124.4 | AP34: =SUM(AH34:AO34) -> 35124.4 | AZ34: =SUM(AQ34:AY34) -> 0 | BK34: =+Q34+AP34+AZ34+BE34+BH34+BI34+BJ34+BG34+AG34+BF34+BA34+BD34+BB34+BC34 -> 35124.4 | BL34: 0 | BM34: =+$BL$34*BM2 -> 0 | BN34: =+$BL$34*BN2 -> 0 | BO34: =+$BL$34*BO2 -> 0 | BP34: =+$BL$34*BP2 -> 0 | BQ34: =+$BL$34*BQ2 -> 0 | BR34: =+$BL$34*BR2 -> 0 | BS34: =+$BL$34*BS2 -> 0 | BT34: =+$BL$34*BT2 -> 0 | ... BW34: =+$BL$34*BW2 -> 0 | BX34: =SUM(BM34:BW34) -> 0 | BY34: =+BK34-BX34 -> 35124.4 | CA34: =+BL34*2080 -> 0
A35: =+A34+1 -> 32 | B35: Faye | Q35: =SUM(C35:P35) -> 0 | AG35: =SUM(R35:AF35) -> 0 | AP35: =SUM(AH35:AO35) -> 0 | AU35: 35551.61 | AZ35: =SUM(AQ35:AY35) -> 35551.61 | BK35: =+Q35+AP35+AZ35+BE35+BH35+BI35+BJ35+BG35+AG35+BF35+BA35+BD35+BB35+BC35 -> 35551.61 | BL35: 30.1809 | BM35: =+$BL$35*BM2 -> 2414.472 | BN35: =+$BL$35*BN2 -> 2414.472 | BO35: =+$BL$35*BO2 -> 2414.472 | BP35: =+$BL$35*BP2 -> 2414.472 | BQ35: =+$BL$35*BQ2 -> 2414.472 | BR35: =+$BL$35*BR2 -> 2414.472 | BS35: =+$BL$35*BS2 -> 2414.472 | BT35: =+$BL$35*BT2 -> 2414.472 | ... BW35: =+$BL$35*BW2 -> 1690.1304 | BX35: =SUM(BM35:BW35) -> 25834.85 | BY35: =+BK35-BX35 -> 9716.7596 | CA35: =+BL35*2080 -> 62776.272
A36: =+A35+1 -> 33 | B36: Ferdawok | F36: 15000 | Q36: =SUM(C36:P36) -> 15000 | AG36: =SUM(R36:AF36) -> 0 | AP36: =SUM(AH36:AO36) -> 0 | AZ36: =SUM(AQ36:AY36) -> 0 | BC36: 909.34 | BD36: 4182.99 | BH36: =441.86+6000 -> 6441.86 | BI36: 0 | BK36: =+Q36+AP36+AZ36+BE36+BH36+BI36+BJ36+BG36+AG36+BF36+BA36+BD36+BB36+BC36 -> 26534.19 | BL36: 28.4171 | BM36: =+$BL$36*BM2 -> 2273.368 | BN36: =+$BL$36*BN2 -> 2273.368 | BO36: =+$BL$36*BO2 -> 2273.368 | BP36: =+$BL$36*BP2 -> 2273.368 | BQ36: =+BP36 -> 2273.368 | BR36: =+BQ36 -> 2273.368 | BS36: =+BR36 -> 2273.368 | BT36: =+BS36 -> 2273.368 | BU36: =+BT36 -> 2273.368 | BV36: =+BU36 -> 2273.368 | BW36: =+BV36 -> 2273.368 | BX36: =SUM(BM36:BW36) -> 25007.048 | BY36: =+BK36-BX36 -> 1527.142 | CA36: =+BL36*2080 -> 59107.568
A37: =+A36+1 -> 34 | B37: Firdus | Q37: =SUM(C37:P37) -> 0 | AG37: =SUM(R37:AF37) -> 0 | AP37: =SUM(AH37:AO37) -> 0 | AZ37: =SUM(AQ37:AY37) -> 0 | BE37: =4031+1536+1386.62+2849.53 -> 9803.15 | BK37: =+Q37+AP37+AZ37+BE37+BH37+BI37+BJ37+BG37+AG37+BF37+BA37+BD37+BB37+BC37 -> 9803.15 | BL37: 24 | BM37: =+$BL$37*56 -> 1344 | BN37: =+BM37 -> 1344 | BO37: =+BN37 -> 1344 | BP37: =+BO37 -> 1344 | BQ37: =+BP37 -> 1344 | BR37: =+BQ37 -> 1344 | BS37: =+BR37 -> 1344 | BT37: 395.15 | BU37: 0 | BV37: 0 | BW37: 0 | BX37: =SUM(BM37:BW37) -> 9803.15 | BY37: =+BK37-BX37 -> 0 | CA37: =+BL37*2080 -> 49920
A38: =+A37+1 -> 35 | B38: Florance | Q38: =SUM(C38:P38) -> 0 | AG38: =SUM(R38:AF38) -> 0 | AP38: =SUM(AH38:AO38) -> 0 | AY38: 43861.32 | AZ38: =SUM(AQ38:AY38) -> 43861.32 | BK38: =+Q38+AP38+AZ38+BE38+BH38+BI38+BJ38+BG38+AG38+BF38+BA38+BD38+BB38+BC38 -> 43861.32 | BL38: 27.7771 | BM38: =+$BL$38*BM2 -> 2222.168 | BN38: =+$BL$38*BN2 -> 2222.168 | BO38: =+$BL$38*BO2 -> 2222.168 | BP38: =+$BL$38*BP2 -> 2222.168 | BQ38: =+$BL$38*BQ2 -> 2222.168 | BR38: =+$BL$38*BR2 -> 2222.168 | BS38: =+$BL$38*BS2 -> 2222.168 | BT38: =+$BL$38*BT2 -> 2222.168 | ... BW38: =+$BL$38*BW2 -> 1555.5176 | BX38: =SUM(BM38:BW38) -> 23777.198 | BY38: =+BK38-BX38 -> 20084.122 | CA38: =+BL38*2080 -> 57776.368
A39: 36 | B39: TBH - Mildred | P39: 16195.95 | Q39: =SUM(C39:P39) -> 16195.95 | AG39: =SUM(R39:AF39) -> 0 | BK39: =+Q39+AP39+AZ39+BE39+BH39+BI39+BJ39+BG39+AG39+BF39+BA39+BD39+BB39+BC39 -> 16195.95 | BY39: =+BK39-BX39 -> 16195.95 | CA39: =+BL39*2080 -> 0
A40: 37 | B40: Freshta Atmar | Q40: =SUM(C40:P40) -> 0 | AG40: =SUM(R40:AF40) -> 0 | AP40: =SUM(AH40:AO40) -> 0 | AT40: 0 | AX40: 20605.76 | AZ40: =SUM(AQ40:AY40) -> 20605.76 | BD40: 6250 | BK40: =+Q40+AP40+AZ40+BE40+BH40+BI40+BJ40+BG40+AG40+BF40+BA40+BD40+BB40+BC40 -> 26855.76 | BL40: 24.0385 | BM40: =+$BL$40*BM2 -> 1923.08 | BN40: =+$BL$40*BN2 -> 1923.08 | BO40: =+$BL$40*BO2 -> 1923.08 | BP40: =+$BL$40*BP2 -> 1923.08 | BQ40: =+$BL$40*BQ2 -> 1923.08 | BR40: =+$BL$40*BR2 -> 1923.08 | BS40: =+$BL$40*BS2 -> 1923.08 | BT40: =+$BL$40*BT2 -> 1923.08 | ... BW40: =+$BL$40*BW2 -> 1346.156 | BX40: =SUM(BM40:BW40) -> 20576.956 | BY40: =+BK40-BX40 -> 6278.804 | CA40: =+BL40*2080 -> 50000.08
A41: =+A40+1 -> 38 | B41: Frishta Khalil | Q41: =SUM(C41:P41) -> 0 | AG41: =SUM(R41:AF41) -> 0 | AH41: 25057.65 | AP41: =SUM(AH41:AO41) -> 25057.65 | AZ41: =SUM(AQ41:AY41) -> 0 | BK41: =+Q41+AP41+AZ41+BE41+BH41+BI41+BJ41+BG41+AG41+BF41+BA41+BD41+BB41+BC41 -> 25057.65 | BL41: 24.0385 | BM41: =$BL$41*BM2 -> 1923.08 | BN41: =$BL$41*BN2 -> 1923.08 | BO41: =$BL$41*BO2 -> 1923.08 | BP41: =$BL$41*BP2 -> 1923.08 | BQ41: =$BL$41*BQ2 -> 1923.08 | BR41: =$BL$41*BR2 -> 1923.08 | BS41: =$BL$41*BS2 -> 1923.08 | BT41: =$BL$41*BT2 -> 1923.08 | ... BW41: =$BL$41*BW2 -> 1346.156 | BX41: =SUM(BM41:BW41) -> 20576.956 | BY41: =+BK41-BX41 -> 4480.694 | CA41: =+BL41*2080 -> 50000.08
...

Sheet FY26
AC2: MORA | AM2: ONA | AV2: MG | AX2: R&P
C3: Hourly Rate | D3: Annual Income | E3: Budget Total | F3: Variance | G3: PC ICM 5208-30 | H3: ASA III 5147-30 | I3: ASA IV 5176-30 | J3: PC UHP 5129-30 | K3: PC UHP V 5211-30 | L3: PC REA III 5209-30 | M3: PC Add. 5227-30 | N3: FY 26 ICM 5240 30 | O3: Total PC VA | P3: PC ICM 5208-33 | Q3: ASA II 5124-33 | R3: ASA III 5147-33 | S3: PC ASA IV 5176-33 | T3: PC UHP II 5145-33 | U3: PC UHP III 5166-33 | V3: PC UHP IV 5175-33 | W3: PC UHP V 5211-33 | X3: PC REA III 5209-33 | Y3: PC Additional 5227-33 | Z3: FY 26 ICM 5240-33 | AA3: Total PC MD | AB3: 2032 RYMP | AC3: 5051 SOR | AD3: 5052 ECMP | AE3: 5059 RSS | AF3: RTCA FY 26 5247 | AG3: RTCA FY 25 5212 | AH3: 5236-CMF #1 Oct-Dec | AI3: 5248 CMF #2 Jan - June | AJ3: 5196 ARSS | AK3: MORA | AL3: 5061 | AM3: 5062 | AN3: 5117 | AO3: 5118 | AP3: 5119 | AQ3: 5151 | AR3: 5214 | AS3: 5215 | AT3: 5216 | AU3: ONA | AV3: MG 5222-33 | AW3: MG 5222-30 | AX3: RP PIR 5245-30 | AY3: PC Initial Resettlement 5245-33 | AZ3: R&P 5213-30 | BA3: R&P 52130-33 | BB3: Total R&P | BC3: AFHS 2103-30 | BD3: Food Securtity Arlington 1060-30 | BE3: VFHY 3002-30 | BF3: DV #1 2025-30 | BG3: DV #2 2126-30 | BH3: NOFO 4007-30 | BI3: VOCA 2060-30 | BJ3: TVAP 2094-30
A4: 1 | B4: Abeer Omer | C4: 24.0385 | D4: =+C4*2080 -> 50000.08 | E4: =+O4+AA4+AK4+AU4+AV4+AW4+BC4+BE4+BF4+BG4+BH4+BI4+BJ4+BB4+BD4 -> 60418.505 | F4: =+E4-D4 -> 10418.425 | N4: 0 | O4: =SUM(G4:N4) -> 0 | Z4: 0 | AA4: =SUM(P4:Z4) -> 0 | AB4: 0 | AC4: 0 | AD4: 0 | AE4: 0 | AF4: 0 | AH4: 0 | AJ4: 0 | AK4: =SUM(AB4:AJ4) -> 0 | AL4: 0 | AM4: 0 | AN4: 0 | AO4: 0 | AP4: 0 | AQ4: 0 | AR4: 0 | AS4: 0 | AT4: 0 | AU4: =SUM(AL4:AT4) -> 0 | AX4: 0 | AY4: 0 | BB4: =SUM(AX4:BA4) -> 0 | BF4: 2500 | BG4: =+'[1]P 2- Salary'!$L$10 -> 48814.275 | BI4: 9104.23 | BL4: =+D4*5% -> 2500.004 | BM4: =+BL4+D4 -> 52500.084
A5: =+A4+1 -> 2 | B5: Aemal Sanjeeda | C5: 26.4423 | D5: =+C5*2080 -> 54999.984 | E5: =+O5+AA5+AK5+AU5+AV5+AW5+BC5+BE5+BF5+BG5+BH5+BI5+BJ5+BB5+BD5 -> 57749 | F5: =+E5-D5 -> 2749.016 | N5: 0 | O5: =SUM(G5:N5) -> 0 | Z5: 0 | AA5: =SUM(P5:Z5) -> 0 | AB5: 0 | AC5: 0 | AD5: 0 | AE5: 0 | AF5: 0 | AH5: 0 | AJ5: 0 | AK5: =SUM(AB5:AJ5) -> 0 | AO5: =+'[2]P 2-Salary '!$J$24 -> 57749 | AU5: =SUM(AL5:AT5) -> 57749 | AX5: 0 | AY5: 0 | BB5: =SUM(AX5:BA5) -> 0 | BL5: =+D5*5% -> 2749.9992 | BM5: =+BL5+D5 -> 57749.983
A6: =+A5+1 -> 3 | B6: Ahmed Seyar Auobi | C6: 24.0385 | D6: =+C6*2080 -> 50000.08 | E6: =+O6+AA6+AK6+AU6+AV6+AW6+BC6+BE6+BF6+BG6+BH6+BI6+BJ6+BB6+BD6 -> 52500 | F6: =+E6-D6 -> 2499.92 | G6: 13125 | N6: 39375 | O6: =SUM(G6:N6) -> 52500 | Z6: 0 | AA6: =SUM(P6:Z6) -> 0 | AB6: 0 | AC6: 0 | AD6: 0 | AE6: 0 | AF6: 0 | AH6: 0 | AJ6: 0 | AK6: =SUM(AB6:AJ6) -> 0 | AU6: =SUM(AL6:AT6) -> 0 | AX6: 0 | AY6: 0 | BB6: =SUM(AX6:BA6) -> 0 | BL6: =+D6*5% -> 2500.004 | BM6: =+BL6+D6 -> 52500.084
A7: =+A6+1 -> 4 | B7: Ajmal Amiri | C7: 25.601 | D7: =+C7*2080 -> 53250.08 | E7: =+O7+AA7+AK7+AU7+AV7+AW7+BC7+BE7+BF7+BG7+BH7+BI7+BJ7+BB7+BD7 -> 74363.16 | F7: =+E7-D7 -> 21113.08 | K7: 7268.56 | L7: 11182.4 | N7: 0 | O7: =SUM(G7:N7) -> 18450.96 | Z7: 0 | AA7: =SUM(P7:Z7) -> 0 | AK7: =SUM(AB7:AJ7) -> 0 | AR7: =+'[4]P 2-Salary '!$J$18 -> 11182.6 | AS7: =+'[5]P 2-Salary '!$J$25 -> 16773.6 | AT7: =+'[6]P 2-Salary '!$J$19 -> 27956 | AU7: =SUM(AL7:AT7) -> 55912.2 | AX7: 0 | AY7: 0 | BB7: =SUM(AX7:BA7) -> 0 | BL7: =+D7*5% -> 2662.504 | BM7: =+BL7+D7 -> 55912.584
A8: =+A7+1 -> 5 | B8: Ajmal Khurram | C8: 24.0385 | D8: =+C8*2080 -> 50000.08 | E8: =+O8+AA8+AK8+AU8+AV8+AW8+BC8+BE8+BF8+BG8+BH8+BI8+BJ8+BB8+BD8 -> 55913 | F8: =+E8-D8 -> 5912.92 | N8: 0 | O8: =SUM(G8:N8) -> 0 | Z8: 0 | AA8: =SUM(P8:Z8) -> 0 | AE8: 55913 | AK8: =SUM(AB8:AJ8) -> 55913 | AU8: =SUM(AL8:AT8) -> 0 | AX8: 0 | AY8: 0 | BB8: =SUM(AX8:BA8) -> 0 | BL8: =+D8*5% -> 2500.004 | BM8: =+BL8+D8 -> 52500.084
A9: =+A8+1 -> 6 | B9: Akilu Debalkew | C9: 24.0385 | D9: =+C9*2080 -> 50000.08 | E9: =+O9+AA9+AK9+AU9+AV9+AW9+BC9+BE9+BF9+BG9+BH9+BI9+BJ9+BB9+BD9 -> 61982.7 | F9: =+E9-D9 -> 11982.62 | G9: 5250 | H9: 1050 | I9: 2100 | J9: 4200 | K9: 1575 | M9: 2625 | N9: 7875 | O9: =SUM(G9:N9) -> 24675 | Z9: 0 | AA9: =SUM(P9:Z9) -> 0 | AG9: 0 | AI9: 0 | AK9: =SUM(AB9:AJ9) -> 0 | AO9: 0 | AU9: =SUM(AL9:AT9) -> 0 | AV9: 0 | AW9: 24000 | AX9: 6000 | AY9: 0 | AZ9: 7307.7 | BB9: =SUM(AX9:BA9) -> 13307.7 | BL9: =+D9*5% -> 2500.004 | BM9: =+BL9+D9 -> 52500.084
A10: =+A9+1 -> 7 | B10: Albab Azeze | C10: 24.0385 | D10: =+C10*2080 -> 50000.08 | E10: =+O10+AA10+AK10+AU10+AV10+AW10+BC10+BE10+BF10+BG10+BH10+BI10+BJ10+BB10+BD10 -> 58157 | F10: =+E10-D10 -> 8156.92 | N10: 0 | O10: =SUM(G10:N10) -> 0 | Z10: 0 | AA10: =SUM(P10:Z10) -> 0 | AE10: 10000 | AF10: 10000 | AG10: =50257-30000+17900 -> 38157 | AK10: =SUM(AB10:AJ10) -> 58157 | AO10: 0 | AU10: =SUM(AL10:AT10) -> 0 | AX10: 0 | AY10: 0 | BB10: =SUM(AX10:BA10) -> 0 | BL10: =+D10*5% -> 2500.004 | BM10: =+BL10+D10 -> 52500.084
A11: =+A10+1 -> 8 | B11: Anna Kurzer | C11: 33.2813 | D11: =+C11*2080 -> 69225.104 | E11: =+O11+AA11+AK11+AU11+AV11+AW11+BC11+BE11+BF11+BG11+BH11+BI11+BJ11+BB11+BD11 -> 70850.7 | F11: =+E11-D11 -> 1625.596 | N11: 0 | O11: =SUM(G11:N11) -> 0 | Z11: 0 | AA11: =SUM(P11:Z11) -> 0 | AF11: 29074 | AG11: =35000+13570-20000-15000-900 -> 12670 | AH11: 5325.01 | AI11: 0 | AJ11: 14280 | AK11: =SUM(AB11:AJ11) -> 61349.01 | AU11: =SUM(AL11:AT11) -> 0 | AV11: 9501.69 | AX11: 0 | AY11: 0 | BB11: =SUM(AX11:BA11) -> 0 | BL11: =+D11*5% -> 3461.2552 | BM11: =+BL11+D11 -> 72686.359
A12: =+A11+1 -> 9 | B12: Atakhleti Alemseged | C12: 32.7064 | D12: =+C12*2080 -> 68029.312 | E12: =+O12+AA12+AK12+AU12+AV12+AW12+BC12+BE12+BF12+BG12+BH12+BI12+BJ12+BB12+BD12 -> 71101.37 | F12: =+E12-D12 -> 3072.058 | I12: 3503.5 | N12: 0 | O12: =SUM(G12:N12) -> 3503.5 | R12: 6306.3 | Z12: 0 | AA12: =SUM(P12:Z12) -> 6306.3 | AD12: 42597 | AH12: 0 | AK12: =SUM(AB12:AJ12) -> 42597 | AU12: =SUM(AL12:AT12) -> 0 | AX12: 0 | AY12: 0 | AZ12: 5219.53 | BB12: =SUM(AX12:BA12) -> 5219.53 | BH12: =26557.58-13082.54 -> 13475.04 | BL12: =+D12*5% -> 3401.4656 | BM12: =+BL12+D12 -> 71430.778
A13: =+A12+1 -> 10 | B13: Barbara Callen | C13: 31.25 | D13: =+C13*2080 -> 65000 | E13: =+O13+AA13+AK13+AU13+AV13+AW13+BC13+BE13+BF13+BG13+BH13+BI13+BJ13+BB13+BD13 -> 93163.75 | F13: =+E13-D13 -> 28163.75 | G13: 2730 | H13: 1365 | J13: 3412.5 | K13: 2047.5 | L13: 3412.5 | M13: 4095 | N13: 2730 | O13: =SUM(G13:N13) -> 19792.5 | P13: 2730 | Q13: 1365 | T13: 2047.5 | U13: 1365 | X13: 2047.5 | Z13: 2047.5 | AA13: =SUM(P13:Z13) -> 11602.5 | AD13: 6825 | AE13: 6825 | AH13: 5625 | AI13: 3250 | AJ13: 6825 | AK13: =SUM(AB13:AJ13) -> 29350 | AN13: =+'[7]P 2-Salary '!$J$24 -> 6825 | AO13: =+'[2]P 2-Salary '!$J$30 -> 6825 | AR13: =+'[4]P 2-Salary '!$J$24 -> 3412.5 | AT13: =+'[6]P 2-Salary '!$J$23 -> 6825 | AU13: =SUM(AL13:AT13) -> 23887.5 | AV13: 0 | AW13: 4550 | AX13: 0 | AY13: 0 | AZ13: 2031.25 | BA13: 0 | BB13: =SUM(AX13:BA13) -> 2031.25 | BI13: 1950 | BL13: =+D13*5% -> 3250 | BM13: =+BL13+D13 -> 68250
A14: =+A13+1 -> 11 | B14: Baryalai Rawan | C14: 32.6923 | D14: =+C14*2080 -> 67999.984 | E14: =+O14+AA14+AK14+AU14+AV14+AW14+BC14+BE14+BF14+BG14+BH14+BI14+BJ14+BB14+BD14 -> 74222 | F14: =+E14-D14 -> 6222.016 | N14: 0 | O14: =SUM(G14:N14) -> 0 | P14: 5712 | Z14: 7140 | AA14: =SUM(P14:Z14) -> 12852 | AB14: 7140 | AC14: 24990 | AD14: 24990 | AH14: 4250 | AK14: =SUM(AB14:AJ14) -> 61370 | AU14: =SUM(AL14:AT14) -> 0 | AX14: 0 | AY14: 0 | BB14: =SUM(AX14:BA14) -> 0 | BL14: =+D14*5% -> 3399.9992 | BM14: =+BL14+D14 -> 71399.983
A15: =+A14+1 -> 12 | B15: Bethelem Alemahyehu | C15: 24.0385 | D15: =+C15*2080 -> 50000.08 | E15: =+O15+AA15+AK15+AU15+AV15+AW15+BC15+BE15+BF15+BG15+BH15+BI15+BJ15+BB15+BD15 -> 52500 | F15: =+E15-D15 -> 2499.92 | N15: 0 | O15: =SUM(G15:N15) -> 0 | Z15: 0 | AA15: =SUM(P15:Z15) -> 0 | AD15: 0 | AE15: 52500 | AK15: =SUM(AB15:AJ15) -> 52500 | AU15: =SUM(AL15:AT15) -> 0 | AX15: 0 | AY15: 0 | BB15: =SUM(AX15:BA15) -> 0 | BL15: =+D15*5% -> 2500.004 | BM15: =+BL15+D15 -> 52500.084
A16: =+A15+1 -> 13 | B16: Bob Elston | C16: 31.25 | D16: =+C16*2080 -> 65000 | E16: =+O16+AA16+AK16+AU16+AV16+AW16+BC16+BE16+BF16+BG16+BH16+BI16+BJ16+BB16+BD16 -> 81485 | F16: =+E16-D16 -> 16485 | G16: 3412.5 | H16: 1365 | J16: 4095 | K16: 2047.5 | L16: 3412.5 | N16: =+'[3]PC Admin & Client (Regular)'!$E$24 -> 2047.5 | O16: =SUM(G16:N16) -> 16380 | P16: 2730 | Q16: 1365 | T16: 2047.5 | U16: 1365 | X16: 2047.5 | Z16: 0 | AA16: =SUM(P16:Z16) -> 9555 | AD16: 6825 | AE16: 6825 | AH16: 4375 | AI16: 3250 | AJ16: 6825 | AK16: =SUM(AB16:AJ16) -> 28100 | AN16: =+'[7]P 2-Salary '!$J$25 -> 6825 | AO16: =+'[2]P 2-Salary '!$J$31 -> 6825 | AR16: =+'[4]P 2-Salary '!$J$25 -> 3412.5 | AT16: =+'[6]P 2-Salary '!$J$25 -> 6825 | AU16: =SUM(AL16:AT16) -> 23887.5 | AV16: 2625 | AX16: 0 | AY16: 0 | AZ16: 937.5 | BB16: =SUM(AX16:BA16) -> 937.5 | BL16: =+D16*5% -> 3250 | BM16: =+BL16+D16 -> 68250
A17: =+A16+1 -> 14 | B17: Dagim McKonnen | C17: 30.5547 | D17: =+C17*2080 -> 63553.776 | E17: =+O17+AA17+AK17+AU17+AV17+AW17+BC17+BE17+BF17+BG17+BH17+BI17+BJ17+BB17+BD17 -> 70398.57 | F17: =+E17-D17 -> 6844.794 | N17: 0 | O17: =SUM(G17:N17) -> 0 | Z17: 0 | AA17: =SUM(P17:Z17) -> 0 | AE17: 66732 | AH17: 3666.57 | AK17: =SUM(AB17:AJ17) -> 70398.57 | AU17: =SUM(AL17:AT17) -> 0 | AX17: 0 | AY17: 0 | BB17: =SUM(AX17:BA17) -> 0 | BL17: =+D17*5% -> 3177.6888 | BM17: =+BL17+D17 -> 66731.465
A18: =+A17+1 -> 15 | B18: Razia Mahrami | C18: 36.5385 | D18: =+C18*2080 -> 76000.08 | E18: =+O18+AA18+AK18+AU18+AV18+AW18+BC18+BE18+BF18+BG18+BH18+BI18+BJ18+BB18+BD18 -> 132948.35 | F18: =+E18-D18 -> 56948.27 | N18: 0 | O18: =SUM(G18:N18) -> 0 | P18: 2907.44 | Q18: 1453.72 | T18: 5814.88 | U18: 5814.88 | X18: 7268.6 | Y18: 3634.3 | Z18: 0 | AA18: =SUM(P18:Z18) -> 26893.82 | AB18: 15960 | AC18: 15960 | AD18: 11970 | AE18: 15960 | AF18: 3192 | AG18: 750 | AH18: 8151.53 | AI18: 15960 | AJ18: 15960 | AK18: =SUM(AB18:AJ18) -> 103863.53 | AU18: =SUM(AL18:AT18) -> 0 | AV18: 0 | AX18: 0 | AY18: 2191 | BB18: =SUM(AX18:BA18) -> 2191 | BL18: =+D18*5% -> 3800.004 | BM18: =+BL18+D18 -> 79800.084
A19: =+A18+1 -> 16 | B19: Earnest Overton | C19: 24.0385 | D19: =+C19*2080 -> 50000.08 | E19: =+O19+AA19+AK19+AU19+AV19+AW19+BC19+BE19+BF19+BG19+BH19+BI19+BJ19+BB19+BD19 -> 52500 | F19: =+E19-D19 -> 2499.92 | N19: 0 | O19: =SUM(G19:N19) -> 0 | Z19: 0 | AA19: =SUM(P19:Z19) -> 0 | AK19: =SUM(AB19:AJ19) -> 0 | AO19: =+'[2]P 2-Salary '!$J$27 -> 52500 | AU19: =SUM(AL19:AT19) -> 52500 | AX19: 0 | AY19: 0 | BB19: =SUM(AX19:BA19) -> 0 | BL19: =+D19*5% -> 2500.004 | BM19: =+BL19+D19 -> 52500.084
A20: =+A19+1 -> 17 | B20: Eftihia Ionnidou | C20: 32.2571 | D20: =+C20*2080 -> 67094.768 | E20: =+O20+AA20+AK20+AU20+AV20+AW20+BC20+BE20+BF20+BG20+BH20+BI20+BJ20+BB20+BD20 -> 70449 | F20: =+E20-D20 -> 3354.232 | N20: 0 | O20: =SUM(G20:N20) -> 0 | Z20: 0 | AA20: =SUM(P20:Z20) -> 0 | AK20: =SUM(AB20:AJ20) -> 0 | AN20: =+'[7]P 2-Salary '!$J$17 -> 70449 | AU20: =SUM(AL20:AT20) -> 70449 | AX20: 0 | AY20: 0 | BB20: =SUM(AX20:BA20) -> 0 | BL20: =+D20*5% -> 3354.7384 | BM20: =+BL20+D20 -> 70449.506
A21: =+A20+1 -> 18 | B21: Egosia Ajeih | C21: 25.601 | D21: =+C21*2080 -> 53250.08 | E21: =+O21+AA21+AK21+AU21+AV21+AW21+BC21+BE21+BF21+BG21+BH21+BI21+BJ21+BB21+BD21 -> 56527.42 | F21: =+E21-D21 -> 3277.34 | N21: 0 | O21: =SUM(G21:N21) -> 0 | Z21: 0 | AA21: =SUM(P21:Z21) -> 0 | AE21: 55913 | AH21: 614.42 | AK21: =SUM(AB21:AJ21) -> 56527.42 | AU21: =SUM(AL21:AT21) -> 0 | AX21: 0 | AY21: 0 | BB21: =SUM(AX21:BA21) -> 0 | BL21: =+D21*5% -> 2662.504 | BM21: =+BL21+D21 -> 55912.584
A22: =+A21+1 -> 19 | B22: Elizaabeth Buara Kamara | C22: 28.161 | D22: =+C22*2080 -> 58574.88 | E22: =+O22+AA22+AK22+AU22+AV22+AW22+BC22+BE22+BF22+BG22+BH22+BI22+BJ22+BB22+BD22 -> 62937.39 | F22: =+E22-D22 -> 4362.51 | N22: 0 | O22: =SUM(G22:N22) -> 0 | Z22: 0 | AA22: =SUM(P22:Z22) -> 0 | AH22: 9687.39 | AI22: 53250 | AK22: =SUM(AB22:AJ22) -> 62937.39 | AU22: =SUM(AL22:AT22) -> 0 | AX22: 0 | AY22: 0 | BB22: =SUM(AX22:BA22) -> 0 | BL22: =+D22*5% -> 2928.744 | BM22: =+BL22+D22 -> 61503.624
A23: =+A22+1 -> 20 | B23: Emebet Ashagre | C23: 33.6539 | D23: =+C23*2080 -> 70000.112 | E23: =+O23+AA23+AK23+AU23+AV23+AW23+BC23+BE23+BF23+BG23+BH23+BI23+BJ23+BB23+BD23 -> 109704.24 | F23: =+E23-D23 -> 39704.132 | G23: 2940 | H23: 1470 | J23: 4410 | K23: 2205 | L23: 3675 | N23: =+'[3]PC Admin & Client (Regular)'!$E$18 -> 2205.0036 | O23: =SUM(G23:N23) -> 16905.004 | P23: 2940 | Q23: 1470 | T23: 2205 | U23: 1470 | W23: 1470 | X23: 2205 | Y23: 2205 | Z23: 0 | AA23: =SUM(P23:Z23) -> 13965 | AB23: 3675 | AD23: 7350 | AE23: 7350 | AF23: 1470 | AH23: 4711.54 | AI23: 3500 | AJ23: 7350 | AK23: =SUM(AB23:AJ23) -> 35406.54 | AL23: =+'[8]P 2-Salary '!$J$19 -> 1470 | AM23: =+'[9]P 2-Salary '!$J$18 -> 2205 | AN23: =+'[7]P 2-Salary '!$J$16 -> 3675 | AO23: =+'[2]P 2-Salary '!$J$16 -> 7350 | AP23: =+'[10]P 2-Salary '!$J$16 -> 2940 | AQ23: =+'[11]P 2-Salary '!$J$16 -> 2940 | AR23: =+'[4]P 2-Salary '!$J$23 -> 3675 | AS23: =+'[5]P 2-Salary '!$J$21 -> 2940 | AT23: =+'[6]P 2-Salary '!$J$22 -> 5880 | AU23: =SUM(AL23:AT23) -> 33075 | AW23: =4900-1600 -> 3300 | AX23: 1800 | AY23: 1470 | AZ23: 1682.7 | BA23: 0 | BB23: =SUM(AX23:BA23) -> 4952.7 | BI23: 2100 | BL23: =+D23*5% -> 3500.0056 | BM23: =+BL23+D23 -> 73500.118
A24: =+A23+1 -> 21 | B24: Esra Bayrakthar | C24: 40.9583 | D24: =+C24*2080 -> 85193.264 | E24: =+O24+AA24+AK24+AU24+AV24+AW24+BC24+BE24+BF24+BG24+BH24+BI24+BJ24+BB24+BD24 -> 99961.19 | F24: =+E24-D24 -> 14767.926 | N24: 0 | O24: =SUM(G24:N24) -> 0 | Q24: 8050.68 | Z24: 0 | AA24: =SUM(P24:Z24) -> 8050.68 | AD24: 0 | AE24: 0 | AH24: 2457.51 | AK24: =SUM(AB24:AJ24) -> 2457.51 | AO24: =+'[2]P 2-Salary '!$J$28 -> 89453 | AU24: =SUM(AL24:AT24) -> 89453 | AX24: 0 | AY24: 0 | BB24: =SUM(AX24:BA24) -> 0 | BL24: =+D24*5% -> 4259.6632 | BM24: =+BL24+D24 -> 89452.927
A25: =+A24+1 -> 22 | B25: Evette Phillips | C25: 20 | D25: =+C25*2040 -> 40800 | E25: =+O25+AA25+AK25+AU25+AV25+AW25+BC25+BE25+BF25+BG25+BH25+BI25+BJ25+BB25+BD25 -> 28111 | F25: =+E25-D25 -> -12689 | N25: 0 | O25: =SUM(G25:N25) -> 0 | Z25: 11466 | AA25: =SUM(P25:Z25) -> 11466 | AH25: 6020 | AI25: 10625 | AK25: =SUM(AB25:AJ25) -> 16645 | AU25: =SUM(AL25:AT25) -> 0 | AX25: 0 | AY25: 0 | BB25: =SUM(AX25:BA25) -> 0 | BC25: 0 | BL25: =+D25*5% -> 2040 | BM25: =+BL25+D25 -> 42840
A26: =+A25+1 -> 23 | B26: Faye Biggs | C26: 30.1809 | D26: =+C26*2080 -> 62776.272 | E26: =+O26+AA26+AK26+AU26+AV26+AW26+BC26+BE26+BF26+BG26+BH26+BI26+BJ26+BB26+BD26 -> 65915 | F26: =+E26-D26 -> 3138.728 | N26: 0 | O26: =SUM(G26:N26) -> 0 | Z26: 0 | AA26: =SUM(P26:Z26) -> 0 | AK26: =SUM(AB26:AJ26) -> 0 | AP26: =+'[10]P 2-Salary '!$J$20 -> 52732 | AQ26: =+'[11]P 2-Salary '!$J$22 -> 13183 | AU26: =SUM(AL26:AT26) -> 65915 | AX26: 0 | AY26: 0 | BB26: =SUM(AX26:BA26) -> 0 | BL26: =+D26*5% -> 3138.8136 | BM26: =+BL26+D26 -> 65915.086
A27: =+A26+1 -> 24 | B27: Ferdawok Woyesa | C27: 28.4171 | D27: =+C27*2080 -> 59107.568 | E27: =+O27+AA27+AK27+AU27+AV27+AW27+BC27+BE27+BF27+BG27+BH27+BI27+BJ27+BB27+BD27 -> 68498.85 | F27: =+E27-D27 -> 9391.282 | N27: 0 | O27: =SUM(G27:N27) -> 0 | Z27: 0 | AA27: =SUM(P27:Z27) -> 0 | AK27: =SUM(AB27:AJ27) -> 0 | AO27: 0 | AU27: =SUM(AL27:AT27) -> 0 | AW27: 0 | AX27: 0 | AY27: 0 | BB27: =SUM(AX27:BA27) -> 0 | BG27: 23834.2 | BI27: 44664.65 | BL27: =+D27*5% -> 2955.3784 | BM27: =+BL27+D27 -> 62062.946
A28: =+A27+1 -> 25 | B28: Firdus Yusuf | C28: 24 | D28: =+C28*56*26 -> 34944 | E28: =+O28+AA28+AK28+AU28+AV28+AW28+BC28+BE28+BF28+BG28+BH28+BI28+BJ28+BB28+BD28 -> 18431.78 | F28: =+E28-D28 -> -16512.22 | N28: 0 | O28: =SUM(G28:N28) -> 0 | Z28: 0 | AA28: =SUM(P28:Z28) -> 0 | AK28: =SUM(AB28:AJ28) -> 0 | AU28: =SUM(AL28:AT28) -> 0 | AX28: 0 | AY28: 0 | BB28: =SUM(AX28:BA28) -> 0 | BC28: 18431.78 | BL28: =+D28*5% -> 1747.2 | BM28: =+BL28+D28 -> 36691.2
A29: =+A28+1 -> 26 | B29: Florance Ahmadi | C29: 27.7771 | D29: =+C29*2080 -> 57776.368 | E29: =+O29+AA29+AK29+AU29+AV29+AW29+BC29+BE29+BF29+BG29+BH29+BI29+BJ29+BB29+BD29 -> 60665 | F29: =+E29-D29 -> 2888.632 | N29: 0 | O29: =SUM(G29:N29) -> 0 | Z29: 0 | AA29: =SUM(P29:Z29) -> 0 | AI29: 0 | AK29: =SUM(AB29:AJ29) -> 0 | AN29: =+'[7]P 2-Salary '!$J$18 -> 60665 | AU29: =SUM(AL29:AT29) -> 60665 | AX29: 0 | AY29: 0 | BB29: =SUM(AX29:BA29) -> 0 | BL29: =+D29*5% -> 2888.8184 | BM29: =+BL29+D29 -> 60665.186
A30: =+A29+1 -> 27 | B30: Freshta Atmar | C30: 24.0385 | D30: =+C30*2080 -> 50000.08 | E30: =+O30+AA30+AK30+AU30+AV30+AW30+BC30+BE30+BF30+BG30+BH30+BI30+BJ30+BB30+BD30 -> 59286.89 | F30: =+E30-D30 -> 9286.81 | N30: 0 | O30: =SUM(G30:N30) -> 0 | Z30: 0 | AA30: =SUM(P30:Z30) -> 0 | AK30: =SUM(AB30:AJ30) -> 0 | AS30: =+'[5]P 2-Salary '!$J$24 -> 26250 | AU30: =SUM(AL30:AT30) -> 26250 | AW30: 30036.89 | AX30: 0 | AY30: 0 | AZ30: 3000 | BA30: 0 | BB30: =SUM(AX30:BA30) -> 3000 | BL30: =+D30*5% -> 2500.004 | BM30: =+BL30+D30 -> 52500.084
A31: =+A30+1 -> 28 | B31: Maternity Frishta Khalil | C31: 24.0385 | D31: =+C31*2080 -> 50000.08 | E31: =+O31+AA31+AK31+AU31+AV31+AW31+BC31+BE31+BF31+BG31+BH31+BI31+BJ31+BB31+BD31 -> 49203 | F31: =+E31-D31 -> -797.08 | N31: 0 | O31: =SUM(G31:N31) -> 0 | Z31: 0 | AA31: =SUM(P31:Z31) -> 0 | AB31: 0 | AE31: 49203 | AK31: =SUM(AB31:AJ31) -> 49203 | AU31: =SUM(AL31:AT31) -> 0 | AX31: 0 | AY31: 0 | BB31: =SUM(AX31:BA31) -> 0 | BL31: =+D31*5% -> 2500.004 | BM31: =+BL31+D31 -> 52500.084
A32: =+A31+1 -> 29 | B32: TBH - Ganna Poskara | C32: 25.601 | D32: =+C32*2080 -> 53250.08 | E32: =+O32+AA32+AK32+AU32+AV32+AW32+BC32+BE32+BF32+BG32+BH32+BI32+BJ32+BB32+BD32 -> 54000 | F32: =+E32-D32 -> 749.92 | N32: 0 | O32: =SUM(G32:N32) -> 0 | Z32: 0 | AA32: =SUM(P32:Z32) -> 0 | AB32: 0 | AC32: 0 | AD32: 0 | AE32: 0 | AF32: 0 | AG32: 0 | AH32: 0 | AJ32: =52500+1500 -> 54000 | AK32: =SUM(AB32:AJ32) -> 54000 | AU32: =SUM(AL32:AT32) -> 0 | AX32: 0 | AY32: 0 | BB32: =SUM(AX32:BA32) -> 0 | BL32: =+D32*5% -> 2662.504 | BM32: =+BL32+D32 -> 55912.584
A33: =+A32+1 -> 30 | B33: TBH - Gelila Woodimagen | C33: 24.0385 | D33: =+C33*2080 -> 50000.08 | E33: =+O33+AA33+AK33+AU33+AV33+AW33+BC33+BE33+BF33+BG33+BH33+BI33+BJ33+BB33+BD33 -> 51000 | F33: =+E33-D33 -> 999.92 | N33: 0 | O33: =SUM(G33:N33) -> 0 | Z33: 0 | AA33: =SUM(P33:Z33) -> 0 | AB33: 0 | AC33: 0 | AD33: 0 | AE33: 0 | AF33: 0 | AH33: 0 | AJ33: =52500-1500 -> 51000 | AK33: =SUM(AB33:AJ33) -> 51000 | AU33: =SUM(AL33:AT33) -> 0 | AX33: 0 | AY33: 0 | BA33: 0 | BB33: =SUM(AX33:BA33) -> 0 | BL33: =+D33*5% -> 2500.004 | BM33: =+BL33+D33 -> 52500.084
A34: =+A33+1 -> 31 | B34: Hamdard Hashmatullah | C34: 31.25 | D34: =+C34*2080 -> 65000 | E34: =+O34+AA34+AK34+AU34+AV34+AW34+BC34+BE34+BF34+BG34+BH34+BI34+BJ34+BB34+BD34 -> 63158.75 | F34: =+E34-D34 -> -1841.25 | H34: 6825 | O34: =SUM(G34:N34) -> 6825 | Z34: 0 | AA34: =SUM(P34:Z34) -> 0 | AB34: 0 | AC34: 0 | AD34: 0 | AE34: 0 | AF34: 0 | AH34: 0 | AI34: 0 | AJ34: 0 | AK34: =SUM(AB34:AJ34) -> 0 | AU34: =SUM(AL34:AT34) -> 0 | AW34: 7386.25 | AX34: 15697.5 | AY34: 0 | AZ34: 33250 | BA34: 0 | BB34: =SUM(AX34:BA34) -> 48947.5 | BL34: =+D34*5% -> 3250 | BM34: =+BL34+D34 -> 68250
A35: =+A34+1 -> 32 | B35: Helen Gebru | C35: 36.05769 | D35: =+C35*2080 -> 74999.995 | E35: =+O35+AA35+AK35+AU35+AV35+AW35+BC35+BE35+BF35+BG35+BH35+BI35+BJ35+BB35+BD35 -> 134724.99 | F35: =+E35-D35 -> 59724.995 | G35: 3150 | H35: 1575 | J35: 4725 | K35: 2362.5 | L35: 3937.5 | N35: 3150 | O35: =SUM(G35:N35) -> 18900 | P35: 3150 | Q35: 1575 | T35: 2362.5 | U35: 1575 | W35: 1575 | X35: 2362.5 | Y35: 2362.5 | Z35: 2362.5 | AA35: =SUM(P35:Z35) -> 17325 | AB35: 3938 | AC35: 0 | AD35: 15750 | AE35: 11813 | AF35: 1575 | AH35: 6634.58 | AI35: 3750 | AJ35: 7875 | AK35: =SUM(AB35:AJ35) -> 51335.58 | AL35: =+'[8]P 2-Salary '!$J$20-1000 -> 575 | AM35: =+'[9]P 2-Salary '!$J$19 -> 2362.5 | AN35: =+'[7]P 2-Salary '!$J$21 -> 3937.5 | AO35: =+'[2]P 2-Salary '!$J$17 -> 7875 | AP35: =+'[10]P 2-Salary '!$J$17 -> 3150 | AQ35: =+'[11]P 2-Salary '!$J$17 -> 3150 | AR35: =+'[4]P 2-Salary '!$J$22 -> 3937.5 | AS35: =+'[5]P 2-Salary '!$J$20 -> 3150 | AT35: =+'[6]P 2-Salary '!$J$21 -> 6300 | AU35: =SUM(AL35:AT35) -> 34437.5 | AV35: 0 | AW35: 5250 | AX35: 1575 | AY35: 1575 | AZ35: 4326.91 | BA35: 0 | BB35: =SUM(AX35:BA35) -> 7476.91 | BL35: =+D35*5% -> 3749.9998 | BM35: =+BL35+D35 -> 78749.995
A36: =+A35+1 -> 33 | B36: Henok Shishige | C36: 24.0385 | D36: =+C36*2080 -> 50000.08 | E36: =+O36+AA36+AK36+AU36+AV36+AW36+BC36+BE36+BF36+BG36+BH36+BI36+BJ36+BB36+BD36 -> 52500 | F36: =+E36-D36 -> 2499.92 | N36: 0 | O36: =SUM(G36:N36) -> 0 | Z36: 0 | AA36: =SUM(P36:Z36) -> 0 | AB36: 0 | AC36: 0 | AD36: 52500 | AE36: 0 | AF36: 0 | AH36: 0 | AJ36: 0 | AK36: =SUM(AB36:AJ36) -> 52500 | AU36: =SUM(AL36:AT36) -> 0 | AX36: 0 | AY36: 0 | BB36: =SUM(AX36:BA36) -> 0 | BC36: 0 | BL36: =+D36*5% -> 2500.004 | BM36: =+BL36+D36 -> 52500.084
A37: =+A36+1 -> 34 | B37: Ibraham Diallo | C37: 25.601 | D37: =+C37*2080 -> 53250.08 | E37: =+O37+AA37+AK37+AU37+AV37+AW37+BC37+BE37+BF37+BG37+BH37+BI37+BJ37+BB37+BD37 -> 56778.09 | F37: =+E37-D37 -> 3528.01 | N37: 0 | O37: =SUM(G37:N37) -> 0 | Z37: 0 | AA37: =SUM(P37:Z37) -> 0 | AB37: 0 | AC37: 2796 | AD37: 10650 | AE37: 10650 | AF37: 26250 | AG37: 4000 | AH37: 2432.09 | AJ37: 0 | AK37: =SUM(AB37:AJ37) -> 56778.09 | AU37: =SUM(AL37:AT37) -> 0 | AX37: 0 | AY37: 0 | BB37: =SUM(AX37:BA37) -> 0 | BL37: =+D37*5% -> 2662.504 | BM37: =+BL37+D37 -> 55912.584
A38: =+A37+1 -> 35 | B38: Iriana Lessen | C38: 31.25 | D38: =+C38*2080 -> 65000 | E38: =+O38+AA38+AK38+AU38+AV38+AW38+BC38+BE38+BF38+BG38+BH38+BI38+BJ38+BB38+BD38 -> 95315 | F38: =+E38-D38 -> 30315 | N38: 0 | O38: =SUM(G38:N38) -> 0 | Q38: 7875 | T38: 8400 | V38: 2625 | W38: 5250 | X38: 5250 | Z38: 0 | AA38: =SUM(P38:Z38) -> 29400 | AB38: 0 | AC38: 0 | AD38: 65915 | AE38: 0 | AF38: 0 | AH38: 0 | AI38: 0 | AJ38: 0 | AK38: =SUM(AB38:AJ38) -> 65915 | AU38: =SUM(AL38:AT38) -> 0 | AX38: 0 | AY38: 0 | BB38: =SUM(AX38:BA38) -> 0 | BL38: =+D38*5% -> 3250 | BM38: =+BL38+D38 -> 68250
A39: =+A38+1 -> 36 | B39: Iryna Gaiduk | C39: 30.5547 | D39: =+C39*2080 -> 63553.776 | E39: =+O39+AA39+AK39+AU39+AV39+AW39+BC39+BE39+BF39+BG39+BH39+BI39+BJ39+BB39+BD39 -> 87417.61 | F39: =+E39-D39 -> 23863.834 | J39: 6673.1 | K39: 5338.48 | L39: 5338.48 | N39: 0 | O39: =SUM(G39:N39) -> 17350.06 | Z39: 0 | AA39: =SUM(P39:Z39) -> 0 | AB39: 0 | AC39: 0 | AD39: 0 | AE39: 0 | AF39: 0 | AH39: 0 | AJ39: 0 | AK39: =SUM(AB39:AJ39) -> 0 | AR39: =+'[4]P 2-Salary '!$J$19 -> 23355.85 | AS39: =+'[5]P 2-Salary '!$J$18 -> 20019.3 | AT39: =+'[6]P 2-Salary '!$J$17 -> 26692.4 | AU39: =SUM(AL39:AT39) -> 70067.55 | AX39: 0 | AY39: 0 | BB39: =SUM(AX39:BA39) -> 0 | BE39: 0 | BH39: 0 | BL39: =+D39*5% -> 3177.6888 | BM39: =+BL39+D39 -> 66731.465
A40: =+A39+1 -> 37 | B40: Isabelle Veron | C40: 24.0385 | D40: =+C40*2080 -> 50000.08 | E40: =+O40+AA40+AK40+AU40+AV40+AW40+BC40+BE40+BF40+BG40+BH40+BI40+BJ40+BB40+BD40 -> 52500 | F40: =+E40-D40 -> 2499.92 | N40: 0 | O40: =SUM(G40:N40) -> 0 | Z40: 0 | AA40: =SUM(P40:Z40) -> 0 | AB40: 52500 | AH40: 0 | AK40: =SUM(AB40:AJ40) -> 52500 | AX40: 0 | AY40: 0 | BB40: =SUM(AX40:BA40) -> 0 | BL40: =+D40*5% -> 2500.004 | BM40: =+BL40+D40 -> 52500.084
A41: =+A40+1 -> 38 | B41: Jamal Noori | C41: 28.161 | D41: =+C41*2080 -> 58574.88 | E41: =+O41+AA41+AK41+AU41+AV41+AW41+BC41+BE41+BF41+BG41+BH41+BI41+BJ41+BB41+BD41 -> 66049.23 | F41: =+E41-D41 -> 7474.35 | N41: 0 | O41: =SUM(G41:N41) -> 0 | Z41: 0 | AA41: =SUM(P41:Z41) -> 0 | AB41: 0 | AC41: 0 | AD41: 0 | AE41: 0 | AF41: 0 | AH41: 0 | AI41: 0 | AJ41: 0 | AK41: =SUM(AB41:AJ41) -> 0 | AS41: =+'[5]P 2-Salary '!$J$23+5000 -> 35751.5 | AU41: =SUM(AL41:AT41) -> 35751.5 | AW41: =17482.34+5500+1215.39+1600 -> 25797.73 | AX41: 0 | AY41: 0 | AZ41: 4500 | BA41: 0 | BB41: =SUM(AX41:BA41) -> 4500 | BL41: =+D41*5% -> 2928.744 | BM41: =+BL41+D41 -> 61503.624
...

Sheet Open Positions
E9: =+F9 -> PC Resettlement | F9: PC Resettlement | G9: PC ICM | H9: RSS | I9: ARSS | J9: 5051 | K9: RTCA | L9: ECMP | M9: RHEO | N9: ASA RHEO | O9: ASA RSS | P9: ASA VRSAP | Q9: ASA MYVA
E10: 5245-30 | F10: 5245-33 | G10: 5240-30 | H10: 5059 | I10: 5196 | J10: SOR | K10: New | L10: 5052 | M10: 5061 | N10: 5117 | O10: 5118 | P10: 5119 | Q10: 5151 | R10: Total
C11: 1 | D11: Maternity Frishta Khalil | E11: 0 | F11: 0 | G11: 0 | H11: =+'FY26'!AE31 -> 49203 | I11: 0 | J11: 0 | K11: 0 | L11: 0 | M11: 0 | N11: 0 | O11: 0 | P11: 0 | Q11: 0 | R11: =SUM(E11:Q11) -> 49203
C12: 2 | D12: =+'FY26'!B32 -> TBH - Ganna Poskara | E12: 0 | F12: 0 | G12: 0 | H12: 0 | I12: =+'FY26'!AJ32 -> 54000 | J12: 0 | K12: 0 | L12: 0 | M12: 0 | N12: 0 | O12: 0 | P12: 0 | Q12: 0 | R12: =SUM(E12:Q12) -> 54000
C13: 3 | D13: =+'FY26'!B33 -> TBH - Gelila Woodimagen | E13: 0 | F13: 0 | G13: 0 | H13: 0 | I13: =+'FY26'!AJ33 -> 51000 | J13: 0 | K13: 0 | L13: 0 | M13: 0 | N13: 0 | O13: 0 | P13: 0 | Q13: 0 | R13: =SUM(E13:Q13) -> 51000
C14: 4 | D14: =+'FY26'!B60 -> TBH - Razia Mahrami | E14: 0 | F14: 0 | G14: 0 | H14: =+'FY26'!AE60 -> 72666 | I14: 0 | J14: 0 | K14: 0 | L14: 0 | M14: 0 | N14: 0 | O14: 0 | P14: 0 | Q14: 0 | R14: =SUM(E14:Q14) -> 72666
C15: 5 | D15: =+'FY26'!B63 -> TBH - Albab | E15: 0 | F15: 0 | G15: 0 | H15: =+'FY26'!AE63 -> 42500 | I15: 0 | J15: 0 | K15: 0 | L15: 0 | M15: 0 | N15: 0 | O15: 0 | P15: 0 | Q15: 0 | R15: =SUM(E15:Q15) -> 42500
C16: 6 | D16: =+'FY26'!B76 -> TBH - Outreach Coordinator | E16: 25000 | F16: =+'FY26'!AY76 -> 13125 | G16: 0 | H16: 0 | I16: 0 | J16: 0 | K16: 0 | L16: 0 | M16: 0 | N16: 0 | O16: 0 | P16: 0 | Q16: 0 | R16: =SUM(E16:Q16) -> 38125
C17: 7 | D17: =+'FY26'!B77 -> TBH - Donation Assistant | E17: 25000 | F17: =+'FY26'!AY77 -> 13125 | G17: 0 | H17: 0 | I17: 0 | J17: 0 | K17: 0 | L17: 0 | M17: 0 | N17: 0 | O17: 0 | P17: 0 | Q17: 0 | R17: =SUM(E17:Q17) -> 38125
C18: 8 | D18: =+'FY26'!B78 -> TBH - Case Manager | E18: 0 | F18: 0 | G18: 0 | H18: 0 | I18: 0 | J18: =+'FY26'!AC78 -> 27500 | K18: 0 | L18: 0 | M18: 0 | N18: 0 | O18: 0 | P18: 0 | Q18: 0 | R18: =SUM(E18:Q18) -> 27500
C19: 9 | D19: =+'FY26'!B78 -> TBH - Case Manager | E19: 0 | F19: 0 | G19: 0 | H19: 0 | I19: 0 | J19: 0 | K19: 52500 | L19: 0 | M19: 0 | N19: 0 | O19: 0 | P19: 0 | Q19: 0 | R19: =SUM(E19:Q19) -> 52500
C20: 10 | D20: =+D19 -> TBH - Case Manager | E20: 0 | F20: 0 | G20: 0 | H20: 0 | I20: 0 | J20: 0 | K20: 0 | L20: 52500 | M20: 0 | N20: 0 | O20: 0 | P20: 0 | Q20: 0 | R20: =SUM(E20:Q20) -> 52500
C21: 11 | D21: =+D20 -> TBH - Case Manager | E21: 0 | F21: 0 | G21: 0 | H21: 52500 | I21: 0 | J21: 0 | K21: 0 | L21: 0 | M21: 0 | N21: 0 | O21: 0 | P21: 0 | Q21: 0 | R21: =SUM(E21:Q21) -> 52500
C22: 12 | D22: =+D21 -> TBH - Case Manager | E22: 0 | F22: 0 | G22: 0 | H22: 52500 | I22: 0 | J22: 0 | K22: 0 | L22: 0 | M22: 0 | N22: 0 | O22: 0 | P22: 0 | Q22: 0 | R22: =SUM(E22:Q22) -> 52500
C23: 13 | D23: =+D22 -> TBH - Case Manager | E23: 0 | F23: 0 | G23: 0 | H23: 0 | I23: 0 | J23: 0 | K23: 0 | L23: 52500 | M23: 0 | N23: 0 | O23: 0 | P23: 0 | Q23: 0 | R23: =SUM(E23:Q23) -> 52500
C24: 14 | D24: =+D22 -> TBH - Case Manager | E24: 50000 | F24: 0 | G24: 0 | H24: 0 | I24: 0 | J24: 0 | K24: 0 | L24: 0 | M24: 0 | N24: 0 | O24: 0 | P24: 0 | Q24: 0 | R24: =SUM(E24:Q24) -> 50000
C25: 15 | D25: =+'FY26'!B74 -> TBH - Annie Phillips | E25: 0 | F25: 0 | G25: 5712 | H25: 0 | I25: 0 | J25: 0 | K25: 0 | L25: 0 | M25: 7140 | N25: 17850 | O25: 0 | P25: 14280 | Q25: 14680 | R25: =SUM(E25:Q25) -> 59662
C26: 16 | D26: =+'FY26'!B91 -> TBH - Ferdawok | E26: 0 | F26: 0 | G26: 0 | H26: 0 | I26: 0 | J26: 0 | K26: 0 | L26: 0 | M26: 0 | N26: 0 | O26: 62062 | P26: 0 | Q26: 0 | R26: =SUM(E26:Q26) -> 62062
C27: 17 | D27: =+'FY26'!B93 -> TBH Job Developer VA | E27: 0 | F27: 0 | G27: 0 | H27: 0 | I27: 0 | J27: 0 | K27: 0 | L27: 0 | M27: 0 | N27: 0 | O27: 55000 | P27: 0 | Q27: 0 | R27: =SUM(E27:Q27) -> 55000
E28: =SUM(E11:E27) -> 100000 | F28: =SUM(F11:F27) -> 26250 | G28: =SUM(G11:G27) -> 5712 | H28: =SUM(H11:H27) -> 269369 | I28: =SUM(I11:I27) -> 105000 | J28: =SUM(J11:J27) -> 27500 | K28: =SUM(K11:K27) -> 52500 | L28: =SUM(L11:L27) -> 105000 | ... R28: =SUM(R11:R27) -> 862343
